Workbook
Name Slicer_City: #N/A

Sheet Customer_Dim
A1: Customer_ID | B1: Name | C1: Age | D1: Gender | E1: City | F1: State | G1: Country | H1: Loyalty_Level | J1: COUNT Functions | P1: Findings | Q1: Formula Used
A2: CUST-1000 | B2: Sheena Bonilla | C2: 55 | D2: Male | E2: Donaldton | F2: North Carolina | G2: USA | H2: Platinum | J2: Count of platinum customer | P2: =COUNTIF(H:H,"Platinum") -> 149 | Q2: COUNTIF
A3: CUST-1001 | B3: Eugene Nelson | C3: 26 | D3: Female | E3: Phillipsmouth | F3: North Dakota | G3: USA | H3: Platinum
A4: CUST-1002 | B4: Dr. Benjamin Price | C4: 29 | D4: Female | E4: Kylebury | F4: Alabama | G4: USA | H4: Platinum | J4: Count of Male customer whose Loyalty_Level is Gold | P4: =COUNTIFS(D:D,"Male",H:H,"Gold") -> 54 | Q4: COUNTIFS
A5: CUST-1003 | B5: Jeremy Harris | C5: 59 | D5: Female | E5: Thomastown | F5: Ohio | G5: USA | H5: Bronze
A6: CUST-1004 | B6: Caroline Collins | C6: 64 | D6: Female | E6: Nicholasshire | F6: California | G6: USA | H6: Silver
A7: CUST-1005 | B7: Christine Vaughn | C7: 24 | D7: Male | E7: East Amandamouth | F7: Oregon | G7: USA | H7: Bronze
A8: CUST-1006 | B8: Amber Jackson | C8: 29 | D8: Female | E8: Deborahborough | F8: South Dakota | G8: USA | H8: Platinum
A9: CUST-1007 | B9: Daniel Boyd | C9: 29 | D9: Female | E9: West Pamelafurt | F9: West Virginia | G9: USA | H9: Bronze
A10: CUST-1008 | B10: Melissa Howard | C10: 53 | D10: Female | E10: Maynardton | F10: New Hampshire | G10: USA | H10: Gold
A11: CUST-1009 | B11: Ms. Maria Leach | C11: 64 | D11: Male | E11: Melissashire | F11: Pennsylvania | G11: USA | H11: Platinum
A12: CUST-1010 | B12: Dominic Page | C12: 53 | D12: Male | E12: Port Michaelburgh | F12: Pennsylvania | G12: USA | H12: Bronze
A13: CUST-1011 | B13: Brian Lopez | C13: 28 | D13: Female | E13: East Krista | F13: New York | G13: USA | H13: Gold
A14: CUST-1012 | B14: Kenneth Lambert | C14: 55 | D14: Female | E14: North Kathryn | F14: Kansas | G14: USA | H14: Platinum
A15: CUST-1013 | B15: Nathan Hernandez | C15: 32 | D15: Female | E15: New Becky | F15: Montana | G15: USA | H15: Silver
A16: CUST-1014 | B16: Ashley Cohen | C16: 53 | D16: Female | E16: Lake Kristamouth | F16: Nebraska | G16: USA | H16: Silver
... A501: CUST-1499 | B501: Philip Pennington | C501: 27 | D501: Female | E501: East Valerieview | F501: Oregon | G501: USA | H501: Platinum

Sheet Product_Dim
A1: Product_ID | B1: Product_Name | C1: Category | D1: Sub_Category | E1: Brand | F1: Cost | G1: Stock
A2: PROD-0 | B2: Brother Laser Printer | C2: Electronics | D2: Computer | E2: Hunt Inc | F2: 112 | G2: 416
A3: PROD-1 | B3: Men's Graphic T-Shirt | C3: Clothing | D3: Tops | E3: Terry-Moore | F3: 343 | G3: 181
A4: PROD-2 | B4: Women's Casual Hoodie | C4: Clothing | D4: Outerwear | E4: Sims Inc | F4: 254 | G4: 352
A5: PROD-3 | B5: Men's Running Jacket | C5: Clothing | D5: Outerwear | E5: Pineda Ltd | F5: 365 | G5: 452
A6: PROD-4 | B6: Women's Yoga Pants | C6: Clothing | D6: Bottoms | E6: Gonzales-Davis | F6: 306 | G6: 487
A7: PROD-5 | B7: Men's Leather Belt | C7: Clothing | D7: Accessories | E7: Baldwin, Garza And Gonzalez | F7: 261 | G7: 59
A8: PROD-6 | B8: Herbal Face Moisturizer | C8: Beauty | D8: Skincare | E8: Davidson Plc | F8: 313 | G8: 350
A9: PROD-7 | B9: LED Table Lamp | C9: Home | D9: Lighting | E9: Harrell Llc | F9: 219 | G9: 170
A10: PROD-8 | B10: Wireless Bluetooth Earbuds | C10: Electronics | D10: Audio | E10: Perez-Johnston | F10: 439 | G10: 142
A11: PROD-9 | B11: Adjustable Dumbbell Set | C11: Sports | D11: Fitness | E11: Hill Plc | F11: 496 | G11: 323
A12: PROD-10 | B12: Ceramic Kitchen Bowl Set | C12: Home | D12: Kitchen | E12: Hamilton Group | F12: 299 | G12: 308
A13: PROD-11 | B13: HD Smart TV Stick | C13: Electronics | D13: Accessories | E13: Gibson, Hobbs And Weaver | F13: 449 | G13: 273
... A101: PROD-99 | B101: Stainless Steel Cookware Set | C101: Home | D101: Kitchen | E101: Campbell Ltd | F101: 201 | G101: 146

Sheet Store_Dim
A1: Store_ID | B1: Store_Name | C1: Region | D1: City | E1: Store_Type
A2: STORE-0 | B2: Rivera-Warner | C2: EAST | D2: Washingtonfurt | E2: Flagship
A3: STORE-1 | B3: Martinez, Adkins And Johnson | C3: NORTH | D3: Danielmouth | E3: Flagship
A4: STORE-2 | B4: Black-Horn | C4: SOUTH | D4: North Nancyview | E4: Outlet
A5: STORE-3 | B5: Johnson-Wright | C5: NORTH | D5: Hoodberg | E5: Outlet
A6: STORE-4 | B6: Alexander Group | C6: SOUTH | D6: Port Sharon | E6: Online
A7: STORE-5 | B7: Gray Ltd | C7: NORTH | D7: New Michaelchester | E7: Outlet
A8: STORE-6 | B8: Benson-Elliott | C8: EAST | D8: Port Josephberg | E8: Online
A9: STORE-7 | B9: Martinez-Mullins | C9: SOUTH | D9: Williamsfurt | E9: Online
A10: STORE-8 | B10: Bean, Jones And Park | C10: WEST | D10: Thompsonborough | E10: Online
A11: STORE-9 | B11: Moore, Padilla And Butler | C11: SOUTH | D11: East Johnstad | E11: Flagship
A12: STORE-10 | B12: Hill, Wagner And Ballard | C12: EAST | D12: East Davidville | E12: Online
... A21: STORE-19 | B21: Mann-Austin | C21: EAST | D21: Vasquezborough | E21: Online

Sheet Sales_Fact
A1: Sales_ID | B1: Order_Date | C1: Customer_ID | D1: Product_ID | E1: Store_ID | F1: Quantity | G1: Unit_Price | H1: Discount | I1: Payment_Type | J1: Total_Amount | K1: Discount Amt | L1: High/Low | M1: Order Value | N1: Price | O1: Month | P1: Year | Q1: Sales[Quantity] | S1: SUM Functions : | T1: Findings | U1: Formula Used
A2: SALE-0 | B2: 45480 | C2: CUST-1409 | D2: PROD-97 | E2: STORE-3 | F2: 1 | G2: 218.04 | H2: 0.09 | I2: CREDIT CARD | J2: 198.4164 | K2: =SALES[[#This Row],[Quantity]]*SALES[[#This Row],[Unit_Price]]*SALES[[#This Row],[Discount]] -> 19.6236 | L2: =IF(SALES[Total_Amount]>=1500,"High","Low") -> Low | M2: =_xlfn.IFS(J2>2000,"Premium",J2>1000,"High",J2<=1000,"Normal") -> Normal | N2: =IF(AND(H2>15%,J2>1000),"High Price","Low Price") -> Low Price | O2: =TEXT(B2,"mmmm") -> July | P2: =YEAR(B2) -> 2024 | Q2: =_xlfn.CONCAT(SALES[[#This Row],[Sales_ID]]," [",SALES[[#This Row],[Quantity]],"]") -> SALE-0 [1] | S2: Total Quantity of products sold. | T2: =SUM(F:F) -> 4958 | U2: SUM
A3: SALE-1 | B3: 45285 | C3: CUST-1467 | D3: PROD-74 | E3: STORE-17 | F3: 3 | G3: 104.47 | H3: 0.27 | I3: PAYPAL | J3: 228.7893 | K3: =SALES[[#This Row],[Quantity]]*SALES[[#This Row],[Unit_Price]]*SALES[[#This Row],[Discount]] -> 84.6207 | L3: =IF(SALES[Total_Amount]>=1500,"High","Low") -> Low | M3: =_xlfn.IFS(J3>2000,"Premium",J3>1000,"High",J3<=1000,"Normal") -> Normal | N3: =IF(AND(H3>15%,J3>1000),"High Price","Low Price") -> Low Price | O3: =TEXT(B3,"mmmm") -> December | P3: =YEAR(B3) -> 2023 | Q3: =_xlfn.CONCAT(SALES[[#This Row],[Sales_ID]]," [",SALES[[#This Row],[Quantity]],"]") -> SALE-1 [3] | S3: Unit price for COD orders. | T3: =SUMIFS(G:G,I:I,"COD") -> 330975.2 | U3: SUMIFS
A4: SALE-2 | B4: 45446 | C4: CUST-1056 | D4: PROD-49 | E4: STORE-8 | F4: 4 | G4: 914.05 | H4: 0.25 | I4: CREDIT CARD | J4: 2742.15 | K4: =SALES[[#This Row],[Quantity]]*SALES[[#This Row],[Unit_Price]]*SALES[[#This Row],[Discount]] -> 914.05 | L4: =IF(SALES[Total_Amount]>=1500,"High","Low") -> High | M4: =_xlfn.IFS(J4>2000,"Premium",J4>1000,"High",J4<=1000,"Normal") -> Premium | N4: =IF(AND(H4>15%,J4>1000),"High Price","Low Price") -> High Price | O4: =TEXT(B4,"mmmm") -> June | P4: =YEAR(B4) -> 2024 | Q4: =_xlfn.CONCAT(SALES[[#This Row],[Sales_ID]]," [",SALES[[#This Row],[Quantity]],"]") -> SALE-2 [4] | S4: The total revenue generated from Credit Card payments. | T4: =SUMIFS(J:J,I:I,"CREDIT CARD") -> 715180.71 | U4: SUMIFS
A5: SALE-3 | B5: 45259 | C5: CUST-1346 | D5: PROD-76 | E5: STORE-8 | F5: 1 | G5: 921.51 | H5: 0.16 | I5: COD | J5: 774.0684 | K5: =SALES[[#This Row],[Quantity]]*SALES[[#This Row],[Unit_Price]]*SALES[[#This Row],[Discount]] -> 147.4416 | L5: =IF(SALES[Total_Amount]>=1500,"High","Low") -> Low | M5: =_xlfn.IFS(J5>2000,"Premium",J5>1000,"High",J5<=1000,"Normal") -> Normal | N5: =IF(AND(H5>15%,J5>1000),"High Price","Low Price") -> Low Price | O5: =TEXT(B5,"mmmm") -> November | P5: =YEAR(B5) -> 2023 | Q5: =_xlfn.CONCAT(SALES[[#This Row],[Sales_ID]]," [",SALES[[#This Row],[Quantity]],"]") -> SALE-3 [1] | S5: Total sales generated by PayPal transactions. | T5: =SUMIF(I:I,"PAYPAL",J:J) -> 756754.57 | U5: SUMIF
A6: SALE-4 | B6: 45297 | C6: CUST-1493 | D6: PROD-59 | E6: STORE-5 | F6: 3 | G6: 745.3 | H6: 0.18 | I6: CREDIT CARD | J6: 1833.438 | K6: =SALES[[#This Row],[Quantity]]*SALES[[#This Row],[Unit_Price]]*SALES[[#This Row],[Discount]] -> 402.462 | L6: =IF(SALES[Total_Amount]>=1500,"High","Low") -> High | M6: =_xlfn.IFS(J6>2000,"Premium",J6>1000,"High",J6<=1000,"Normal") -> High | N6: =IF(AND(H6>15%,J6>1000),"High Price","Low Price") -> High Price | O6: =TEXT(B6,"mmmm") -> January | P6: =YEAR(B6) -> 2024 | Q6: =_xlfn.CONCAT(SALES[[#This Row],[Sales_ID]]," [",SALES[[#This Row],[Quantity]],"]") -> SALE-4 [3] | S6: Total discount amount given across all orders. | T6: =SUM(K:K) -> 381571.38 | U6: SUM
A7: SALE-5 | B7: 45499 | C7: CUST-1116 | D7: PROD-15 | E7: STORE-7 | F7: 3 | G7: 147.01 | H7: 0.19 | I7: COD | J7: 357.2343 | K7: =SALES[[#This Row],[Quantity]]*SALES[[#This Row],[Unit_Price]]*SALES[[#This Row],[Discount]] -> 83.7957 | L7: =IF(SALES[Total_Amount]>=1500,"High","Low") -> Low | M7: =_xlfn.IFS(J7>2000,"Premium",J7>1000,"High",J7<=1000,"Normal") -> Normal | N7: =IF(AND(H7>15%,J7>1000),"High Price","Low Price") -> Low Price | O7: =TEXT(B7,"mmmm") -> July | P7: =YEAR(B7) -> 2024 | Q7: =_xlfn.CONCAT(SALES[[#This Row],[Sales_ID]]," [",SALES[[#This Row],[Quantity]],"]") -> SALE-5 [3]
A8: SALE-6 | B8: 45850 | C8: CUST-1016 | D8: PROD-56 | E8: STORE-4 | F8: 2 | G8: 785.31 | H8: 0.15 | I8: PAYPAL | J8: 1335.027 | K8: =SALES[[#This Row],[Quantity]]*SALES[[#This Row],[Unit_Price]]*SALES[[#This Row],[Discount]] -> 235.593 | L8: =IF(SALES[Total_Amount]>=1500,"High","Low") -> Low | M8: =_xlfn.IFS(J8>2000,"Premium",J8>1000,"High",J8<=1000,"Normal") -> High | N8: =IF(AND(H8>15%,J8>1000),"High Price","Low Price") -> Low Price | O8: =TEXT(B8,"mmmm") -> July | P8: =YEAR(B8) -> 2025 | Q8: =_xlfn.CONCAT(SALES[[#This Row],[Sales_ID]]," [",SALES[[#This Row],[Quantity]],"]") -> SALE-6 [2] | S8: IF Function : | T8: Findings | U8: Formula Used
A9: SALE-7 | B9: 45248 | C9: CUST-1152 | D9: PROD-70 | E9: STORE-8 | F9: 4 | G9: 342.39 | H9: 0.23 | I9: PAYPAL | J9: 1054.5612 | K9: =SALES[[#This Row],[Quantity]]*SALES[[#This Row],[Unit_Price]]*SALES[[#This Row],[Discount]] -> 314.9988 | L9: =IF(SALES[Total_Amount]>=1500,"High","Low") -> Low | M9: =_xlfn.IFS(J9>2000,"Premium",J9>1000,"High",J9<=1000,"Normal") -> High | N9: =IF(AND(H9>15%,J9>1000),"High Price","Low Price") -> High Price | O9: =TEXT(B9,"mmmm") -> November | P9: =YEAR(B9) -> 2023 | Q9: =_xlfn.CONCAT(SALES[[#This Row],[Sales_ID]]," [",SALES[[#This Row],[Quantity]],"]") -> SALE-7 [4] | S9: Created column as High/Low for Total amount greater than 1500 | T9: Refer L | U9: IF
A10: SALE-8 | B10: 45781 | C10: CUST-1187 | D10: PROD-99 | E10: STORE-5 | F10: 2 | G10: 448.25 | H10: 0.07 | I10: PAYPAL | J10: 1250.6175 | K10: =SALES[[#This Row],[Quantity]]*SALES[[#This Row],[Unit_Price]]*SALES[[#This Row],[Discount]] -> 62.755 | L10: =IF(SALES[Total_Amount]>=1500,"High","Low") -> Low | M10: =_xlfn.IFS(J10>2000,"Premium",J10>1000,"High",J10<=1000,"Normal") -> High | N10: =IF(AND(H10>15%,J10>1000),"High Price","Low Price") -> Low Price | O10: =TEXT(B10,"mmmm") -> May | P10: =YEAR(B10) -> 2025 | Q10: =_xlfn.CONCAT(SALES[[#This Row],[Sales_ID]]," [",SALES[[#This Row],[Quantity]],"]") -> SALE-8 [2] | S10: Created column as Order Value for below details: | T10: Refer M | U10: IFS
A11: SALE-9 | B11: 45869 | C11: CUST-1464 | D11: PROD-33 | E11: STORE-0 | F11: 2 | G11: 873.17 | H11: 0.23 | I11: PAYPAL | J11: 1344.6818 | K11: =SALES[[#This Row],[Quantity]]*SALES[[#This Row],[Unit_Price]]*SALES[[#This Row],[Discount]] -> 401.6582 | L11: =IF(SALES[Total_Amount]>=1500,"High","Low") -> Low | M11: =_xlfn.IFS(J11>2000,"Premium",J11>1000,"High",J11<=1000,"Normal") -> High | N11: =IF(AND(H11>15%,J11>1000),"High Price","Low Price") -> High Price | O11: =TEXT(B11,"mmmm") -> July | P11: =YEAR(B11) -> 2025 | Q11: =_xlfn.CONCAT(SALES[[#This Row],[Sales_ID]]," [",SALES[[#This Row],[Quantity]],"]") -> SALE-9 [2] | S11: Premium - Greater than 2000
A12: SALE-10 | B12: 45335 | C12: CUST-1065 | D12: PROD-24 | E12: STORE-14 | F12: 1 | G12: 278.63 | H12: 0.07 | I12: CREDIT CARD | J12: 259.1259 | K12: =SALES[[#This Row],[Quantity]]*SALES[[#This Row],[Unit_Price]]*SALES[[#This Row],[Discount]] -> 19.5041 | L12: =IF(SALES[Total_Amount]>=1500,"High","Low") -> Low | M12: =_xlfn.IFS(J12>2000,"Premium",J12>1000,"High",J12<=1000,"Normal") -> Normal | N12: =IF(AND(H12>15%,J12>1000),"High Price","Low Price") -> Low Price | O12: =TEXT(B12,"mmmm") -> February | P12: =YEAR(B12) -> 2024 | Q12: =_xlfn.CONCAT(SALES[[#This Row],[Sales_ID]]," [",SALES[[#This Row],[Quantity]],"]") -> SALE-10 [1] | S12: High - Greater than 1000
A13: SALE-11 | B13: 45801 | C13: CUST-1320 | D13: PROD-39 | E13: STORE-1 | F13: 4 | G13: 286.92 | H13: 0.17 | I13: CREDIT CARD | J13: 952.5744 | K13: =SALES[[#This Row],[Quantity]]*SALES[[#This Row],[Unit_Price]]*SALES[[#This Row],[Discount]] -> 195.1056 | L13: =IF(SALES[Total_Amount]>=1500,"High","Low") -> Low | M13: =_xlfn.IFS(J13>2000,"Premium",J13>1000,"High",J13<=1000,"Normal") -> Normal | N13: =IF(AND(H13>15%,J13>1000),"High Price","Low Price") -> Low Price | O13: =TEXT(B13,"mmmm") -> May | P13: =YEAR(B13) -> 2025 | Q13: =_xlfn.CONCAT(SALES[[#This Row],[Sales_ID]]," [",SALES[[#This Row],[Quantity]],"]") -> SALE-11 [4] | S13: Normal - Less than 1000
A14: SALE-12 | B14: 45528 | C14: CUST-1237 | D14: PROD-88 | E14: STORE-4 | F14: 4 | G14: 644.58 | H14: 0.01 | I14: CREDIT CARD | J14: 2552.5368 | K14: =SALES[[#This Row],[Quantity]]*SALES[[#This Row],[Unit_Price]]*SALES[[#This Row],[Discount]] -> 25.7832 | L14: =IF(SALES[Total_Amount]>=1500,"High","Low") -> High | M14: =_xlfn.IFS(J14>2000,"Premium",J14>1000,"High",J14<=1000,"Normal") -> Premium | N14: =IF(AND(H14>15%,J14>1000),"High Price","Low Price") -> Low Price | O14: =TEXT(B14,"mmmm") -> August | P14: =YEAR(B14) -> 2024 | Q14: =_xlfn.CONCAT(SALES[[#This Row],[Sales_ID]]," [",SALES[[#This Row],[Quantity]],"]") -> SALE-12 [4] | S14: Created column as Price for Discount >15 % and Total Amount >1000 | T14: Refer N | U14: IF and AND
A15: SALE-13 | B15: 45875 | C15: CUST-1443 | D15: PROD-34 | E15: STORE-16 | F15: 2 | G15: 316.9 | H15: 0.3 | I15: PAYPAL | J15: 443.66 | K15: =SALES[[#This Row],[Quantity]]*SALES[[#This Row],[Unit_Price]]*SALES[[#This Row],[Discount]] -> 190.14 | L15: =IF(SALES[Total_Amount]>=1500,"High","Low") -> Low | M15: =_xlfn.IFS(J15>2000,"Premium",J15>1000,"High",J15<=1000,"Normal") -> Normal | N15: =IF(AND(H15>15%,J15>1000),"High Price","Low Price") -> Low Price | O15: =TEXT(B15,"mmmm") -> August | P15: =YEAR(B15) -> 2025 | Q15: =_xlfn.CONCAT(SALES[[#This Row],[Sales_ID]]," [",SALES[[#This Row],[Quantity]],"]") -> SALE-13 [2]
A16: SALE-14 | B16: 45829 | C16: CUST-1348 | D16: PROD-24 | E16: STORE-15 | F16: 4 | G16: 403.47 | H16: 0.29 | I16: PAYPAL | J16: 1145.8548 | K16: =SALES[[#This Row],[Quantity]]*SALES[[#This Row],[Unit_Price]]*SALES[[#This Row],[Discount]] -> 468.0252 | L16: =IF(SALES[Total_Amount]>=1500,"High","Low") -> Low | M16: =_xlfn.IFS(J16>2000,"Premium",J16>1000,"High",J16<=1000,"Normal") -> High | N16: =IF(AND(H16>15%,J16>1000),"High Price","Low Price") -> High Price | O16: =TEXT(B16,"mmmm") -> June | P16: =YEAR(B16) -> 2025 | Q16: =_xlfn.CONCAT(SALES[[#This Row],[Sales_ID]]," [",SALES[[#This Row],[Quantity]],"]") -> SALE-14 [4] | S16: Average : | T16: Findings | U16: Formula Used
A17: SALE-15 | B17: 45636 | C17: CUST-1435 | D17: PROD-36 | E17: STORE-9 | F17: 2 | G17: 871.34 | H17: 0.04 | I17: COD | J17: 2509.4592 | K17: =SALES[[#This Row],[Quantity]]*SALES[[#This Row],[Unit_Price]]*SALES[[#This Row],[Discount]] -> 69.7072 | L17: =IF(SALES[Total_Amount]>=1500,"High","Low") -> High | M17: =_xlfn.IFS(J17>2000,"Premium",J17>1000,"High",J17<=1000,"Normal") -> Premium | N17: =IF(AND(H17>15%,J17>1000),"High Price","Low Price") -> Low Price | O17: =TEXT(B17,"mmmm") -> December | P17: =YEAR(B17) -> 2024 | Q17: =_xlfn.CONCAT(SALES[[#This Row],[Sales_ID]]," [",SALES[[#This Row],[Quantity]],"]") -> SALE-15 [2] | S17: Average of unit price | T17: =AVERAGE(G2:G20) -> 516.59158 | U17: AVERAGE
A18: SALE-16 | B18: 45913 | C18: CUST-1276 | D18: PROD-65 | E18: STORE-19 | F18: 2 | G18: 451.98 | H18: 0.25 | I18: CREDIT CARD | J18: 677.97 | K18: =SALES[[#This Row],[Quantity]]*SALES[[#This Row],[Unit_Price]]*SALES[[#This Row],[Discount]] -> 225.99 | L18: =IF(SALES[Total_Amount]>=1500,"High","Low") -> Low | M18: =_xlfn.IFS(J18>2000,"Premium",J18>1000,"High",J18<=1000,"Normal") -> Normal | N18: =IF(AND(H18>15%,J18>1000),"High Price","Low Price") -> Low Price | O18: =TEXT(B18,"mmmm") -> September | P18: =YEAR(B18) -> 2025 | Q18: =_xlfn.CONCAT(SALES[[#This Row],[Sales_ID]]," [",SALES[[#This Row],[Quantity]],"]") -> SALE-16 [2] | S18: Average Quantity Sold per Order | T18: =AVERAGE(F2:F20) -> 2.5263158 | U18: AVERAGE
A19: SALE-17 | B19: 45637 | C19: CUST-1079 | D19: PROD-27 | E19: STORE-4 | F19: 2 | G19: 502.69 | H19: 0.23 | I19: CREDIT CARD | J19: 774.1426 | K19: =SALES[[#This Row],[Quantity]]*SALES[[#This Row],[Unit_Price]]*SALES[[#This Row],[Discount]] -> 231.2374 | L19: =IF(SALES[Total_Amount]>=1500,"High","Low") -> Low | M19: =_xlfn.IFS(J19>2000,"Premium",J19>1000,"High",J19<=1000,"Normal") -> Normal | N19: =IF(AND(H19>15%,J19>1000),"High Price","Low Price") -> Low Price | O19: =TEXT(B19,"mmmm") -> December | P19: =YEAR(B19) -> 2024 | Q19: =_xlfn.CONCAT(SALES[[#This Row],[Sales_ID]]," [",SALES[[#This Row],[Quantity]],"]") -> SALE-17 [2] | S19: Average of Total Amount for orders where Payment Type is PayPal. | T19: =AVERAGEIF(I:I,"PAYPAL",J:J) -> 1088.8555 | U19: AVERAGEIF
A20: SALE-18 | B20: 45517 | C20: CUST-1094 | D20: PROD-39 | E20: STORE-4 | F20: 2 | G20: 559.23 | H20: 0.25 | I20: COD | J20: 838.845 | K20: =SALES[[#This Row],[Quantity]]*SALES[[#This Row],[Unit_Price]]*SALES[[#This Row],[Discount]] -> 279.615 | L20: =IF(SALES[Total_Amount]>=1500,"High","Low") -> Low | M20: =_xlfn.IFS(J20>2000,"Premium",J20>1000,"High",J20<=1000,"Normal") -> Normal | N20: =IF(AND(H20>15%,J20>1000),"High Price","Low Price") -> Low Price | O20: =TEXT(B20,"mmmm") -> August | P20: =YEAR(B20) -> 2024 | Q20: =_xlfn.CONCAT(SALES[[#This Row],[Sales_ID]]," [",SALES[[#This Row],[Quantity]],"]") -> SALE-18 [2] | S20: Average of Total Amount for orders where Payment Type is Credit Card and Quantity is greater than 2. | T20: =AVERAGEIFS(J:J,I:I,"CREDIT CARD",F:F,">2") -> 1567.4532 | U20: AVERAGEIFS
A21: SALE-19 | B21: 45369 | C21: CUST-1239 | D21: PROD-60 | E21: STORE-13 | F21: 4 | G21: =SALES[[#This Row],[Total_Amount]]/(SALES[[#This Row],[Quantity]]*(1-SALES[[#This Row],[Discount]])) -> 464.18 | H21: 0.04 | I21: COD | J21: 1782.4512 | K21: =SALES[[#This Row],[Quantity]]*SALES[[#This Row],[Unit_Price]]*SALES[[#This Row],[Discount]] -> 74.2688 | L21: =IF(SALES[Total_Amount]>=1500,"High","Low") -> High | M21: =_xlfn.IFS(J21>2000,"Premium",J21>1000,"High",J21<=1000,"Normal") -> High | N21: =IF(AND(H21>15%,J21>1000),"High Price","Low Price") -> Low Price | O21: =TEXT(B21,"mmmm") -> March | P21: =YEAR(B21) -> 2024 | Q21: =_xlfn.CONCAT(SALES[[#This Row],[Sales_ID]]," [",SALES[[#This Row],[Quantity]],"]") -> SALE-19 [4]
A22: SALE-20 | B22: 45843 | C22: CUST-1144 | D22: PROD-72 | E22: STORE-17 | F22: 3 | G22: 986.04 | H22: 0.27 | I22: COD | J22: 2159.4276 | K22: =SALES[[#This Row],[Quantity]]*SALES[[#This Row],[Unit_Price]]*SALES[[#This Row],[Discount]] -> 798.6924 | L22: =IF(SALES[Total_Amount]>=1500,"High","Low") -> High | M22: =_xlfn.IFS(J22>2000,"Premium",J22>1000,"High",J22<=1000,"Normal") -> Premium | N22: =IF(AND(H22>15%,J22>1000),"High Price","Low Price") -> High Price | O22: =TEXT(B22,"mmmm") -> July | P22: =YEAR(B22) -> 2025 | Q22: =_xlfn.CONCAT(SALES[[#This Row],[Sales_ID]]," [",SALES[[#This Row],[Quantity]],"]") -> SALE-20 [3] | S22: Text : | T22: Findings | U22: Formula Used
A23: SALE-21 | B23: 45447 | C23: CUST-1396 | D23: PROD-43 | E23: STORE-18 | F23: 1 | G23: 589.56 | H23: 0.22 | I23: CREDIT CARD | J23: 459.8568 | K23: =SALES[[#This Row],[Quantity]]*SALES[[#This Row],[Unit_Price]]*SALES[[#This Row],[Discount]] -> 129.7032 | L23: =IF(SALES[Total_Amount]>=1500,"High","Low") -> Low | M23: =_xlfn.IFS(J23>2000,"Premium",J23>1000,"High",J23<=1000,"Normal") -> Normal | N23: =IF(AND(H23>15%,J23>1000),"High Price","Low Price") -> Low Price | O23: =TEXT(B23,"mmmm") -> June | P23: =YEAR(B23) -> 2024 | Q23: =_xlfn.CONCAT(SALES[[#This Row],[Sales_ID]]," [",SALES[[#This Row],[Quantity]],"]") -> SALE-21 [1] | S23: Merge Sale_ID and Quantity | T23: Refer Q | U23: CONCAT
A24: SALE-22 | B24: 45394 | C24: CUST-1476 | D24: PROD-69 | E24: STORE-10 | F24: 3 | G24: 979.42 | H24: 0.03 | I24: PAYPAL | J24: 2850.1122 | K24: =SALES[[#This Row],[Quantity]]*SALES[[#This Row],[Unit_Price]]*SALES[[#This Row],[Discount]] -> 88.1478 | L24: =IF(SALES[Total_Amount]>=1500,"High","Low") -> High | M24: =_xlfn.IFS(J24>2000,"Premium",J24>1000,"High",J24<=1000,"Normal") -> Premium | N24: =IF(AND(H24>15%,J24>1000),"High Price","Low Price") -> Low Price | O24: =TEXT(B24,"mmmm") -> April | P24: =YEAR(B24) -> 2024 | Q24: =_xlfn.CONCAT(SALES[[#This Row],[Sales_ID]]," [",SALES[[#This Row],[Quantity]],"]") -> SALE-22 [3] | S24: Only Year in Order_Date Column | T24: Refer P | U24: YEAR
A25: SALE-23 | B25: 45466 | C25: CUST-1368 | D25: PROD-12 | E25: STORE-8 | F25: 1 | G25: 719.28 | H25: 0.08 | I25: CREDIT CARD | J25: 661.7376 | K25: =SALES[[#This Row],[Quantity]]*SALES[[#This Row],[Unit_Price]]*SALES[[#This Row],[Discount]] -> 57.5424 | L25: =IF(SALES[Total_Amount]>=1500,"High","Low") -> Low | M25: =_xlfn.IFS(J25>2000,"Premium",J25>1000,"High",J25<=1000,"Normal") -> Normal | N25: =IF(AND(H25>15%,J25>1000),"High Price","Low Price") -> Low Price | O25: =TEXT(B25,"mmmm") -> June | P25: =YEAR(B25) -> 2024 | Q25: =_xlfn.CONCAT(SALES[[#This Row],[Sales_ID]]," [",SALES[[#This Row],[Quantity]],"]") -> SALE-23 [1] | S25: Month in Text | T25: Refer O | U25: TEXT
A26: SALE-24 | B26: 45908 | C26: CUST-1186 | D26: PROD-67 | E26: STORE-6 | F26: 3 | G26: 77.6 | H26: 0.07 | I26: CREDIT CARD | J26: 216.504 | K26: =SALES[[#This Row],[Quantity]]*SALES[[#This Row],[Unit_Price]]*SALES[[#This Row],[Discount]] -> 16.296 | L26: =IF(SALES[Total_Amount]>=1500,"High","Low") -> Low | M26: =_xlfn.IFS(J26>2000,"Premium",J26>1000,"High",J26<=1000,"Normal") -> Normal | N26: =IF(AND(H26>15%,J26>1000),"High Price","Low Price") -> Low Price | O26: =TEXT(B26,"mmmm") -> September | P26: =YEAR(B26) -> 2025 | Q26: =_xlfn.CONCAT(SALES[[#This Row],[Sales_ID]]," [",SALES[[#This Row],[Quantity]],"]") -> SALE-24 [3]
A27: SALE-25 | B27: 45552 | C27: CUST-1381 | D27: PROD-5 | E27: STORE-3 | F27: 4 | G27: 852.71 | H27: 0.14 | I27: PAYPAL | J27: 2933.3224 | K27: =SALES[[#This Row],[Quantity]]*SALES[[#This Row],[Unit_Price]]*SALES[[#This Row],[Discount]] -> 477.5176 | L27: =IF(SALES[Total_Amount]>=1500,"High","Low") -> High | M27: =_xlfn.IFS(J27>2000,"Premium",J27>1000,"High",J27<=1000,"Normal") -> Premium | N27: =IF(AND(H27>15%,J27>1000),"High Price","Low Price") -> Low Price | O27: =TEXT(B27,"mmmm") -> September | P27: =YEAR(B27) -> 2024 | Q27: =_xlfn.CONCAT(SALES[[#This Row],[Sales_ID]]," [",SALES[[#This Row],[Quantity]],"]") -> SALE-25 [4]
A28: SALE-26 | B28: 45294 | C28: CUST-1213 | D28: PROD-98 | E28: STORE-8 | F28: 4 | G28: 156.16 | H28: 0.15 | I28: CREDIT CARD | J28: 599.6544 | K28: =SALES[[#This Row],[Quantity]]*SALES[[#This Row],[Unit_Price]]*SALES[[#This Row],[Discount]] -> 93.696 | L28: =IF(SALES[Total_Amount]>=1500,"High","Low") -> Low | M28: =_xlfn.IFS(J28>2000,"Premium",J28>1000,"High",J28<=1000,"Normal") -> Normal | N28: =IF(AND(H28>15%,J28>1000),"High Price","Low Price") -> Low Price | O28: =TEXT(B28,"mmmm") -> January | P28: =YEAR(B28) -> 2024 | Q28: =_xlfn.CONCAT(SALES[[#This Row],[Sales_ID]]," [",SALES[[#This Row],[Quantity]],"]") -> SALE-26 [4]
A29: SALE-27 | B29: 45710 | C29: CUST-1200 | D29: PROD-77 | E29: STORE-8 | F29: 3 | G29: 815.49 | H29: 0.17 | I29: CREDIT CARD | J29: 2030.5701 | K29: =SALES[[#This Row],[Quantity]]*SALES[[#This Row],[Unit_Price]]*SALES[[#This Row],[Discount]] -> 415.8999 | L29: =IF(SALES[Total_Amount]>=1500,"High","Low") -> High | M29: =_xlfn.IFS(J29>2000,"Premium",J29>1000,"High",J29<=1000,"Normal") -> Premium | N29: =IF(AND(H29>15%,J29>1000),"High Price","Low Price") -> High Price | O29: =TEXT(B29,"mmmm") -> February | P29: =YEAR(B29) -> 2025 | Q29: =_xlfn.CONCAT(SALES[[#This Row],[Sales_ID]]," [",SALES[[#This Row],[Quantity]],"]") -> SALE-27 [3]
A30: SALE-28 | B30: 45923 | C30: CUST-1148 | D30: PROD-13 | E30: STORE-2 | F30: 2 | G30: 74.21 | H30: 0.11 | I30: PAYPAL | J30: 132.0938 | K30: =SALES[[#This Row],[Quantity]]*SALES[[#This Row],[Unit_Price]]*SALES[[#This Row],[Discount]] -> 16.3262 | L30: =IF(SALES[Total_Amount]>=1500,"High","Low") -> Low | M30: =_xlfn.IFS(J30>2000,"Premium",J30>1000,"High",J30<=1000,"Normal") -> Normal | N30: =IF(AND(H30>15%,J30>1000),"High Price","Low Price") -> Low Price | O30: =TEXT(B30,"mmmm") -> September | P30: =YEAR(B30) -> 2025 | Q30: =_xlfn.CONCAT(SALES[[#This Row],[Sales_ID]]," [",SALES[[#This Row],[Quantity]],"]") -> SALE-28 [2]
A31: SALE-29 | B31: 45302 | C31: CUST-1348 | D31: PROD-99 | E31: STORE-3 | F31: 2 | G31: 451.67 | H31: 0.15 | I31: CREDIT CARD | J31: 1535.678 | K31: =SALES[[#This Row],[Quantity]]*SALES[[#This Row],[Unit_Price]]*SALES[[#This Row],[Discount]] -> 135.501 | L31: =IF(SALES[Total_Amount]>=1500,"High","Low") -> High | M31: =_xlfn.IFS(J31>2000,"Premium",J31>1000,"High",J31<=1000,"Normal") -> High | N31: =IF(AND(H31>15%,J31>1000),"High Price","Low Price") -> Low Price | O31: =TEXT(B31,"mmmm") -> January | P31: =YEAR(B31) -> 2024 | Q31: =_xlfn.CONCAT(SALES[[#This Row],[Sales_ID]]," [",SALES[[#This Row],[Quantity]],"]") -> SALE-29 [2]
A32: SALE-30 | B32: 45217 | C32: CUST-1028 | D32: PROD-5 | E32: STORE-19 | F32: 1 | G32: 429.38 | H32: 0.13 | I32: PAYPAL | J32: 373.5606 | K32: =SALES[[#This Row],[Quantity]]*SALES[[#This Row],[Unit_Price]]*SALES[[#This Row],[Discount]] -> 55.8194 | L32: =IF(SALES[Total_Amount]>=1500,"High","Low") -> Low | M32: =_xlfn.IFS(J32>2000,"Premium",J32>1000,"High",J32<=1000,"Normal") -> Normal | N32: =IF(AND(H32>15%,J32>1000),"High Price","Low Price") -> Low Price | O32: =TEXT(B32,"mmmm") -> October | P32: =YEAR(B32) -> 2023 | Q32: =_xlfn.CONCAT(SALES[[#This Row],[Sales_ID]]," [",SALES[[#This Row],[Quantity]],"]") -> SALE-30 [1]
A33: SALE-31 | B33: 45593 | C33: CUST-1412 | D33: PROD-53 | E33: STORE-12 | F33: 2 | G33: 148.96 | H33: 0.03 | I33: COD | J33: 288.9824 | K33: =SALES[[#This Row],[Quantity]]*SALES[[#This Row],[Unit_Price]]*SALES[[#This Row],[Discount]] -> 8.9376 | L33: =IF(SALES[Total_Amount]>=1500,"High","Low") -> Low | M33: =_xlfn.IFS(J33>2000,"Premium",J33>1000,"High",J33<=1000,"Normal") -> Normal | N33: =IF(AND(H33>15%,J33>1000),"High Price","Low Price") -> Low Price | O33: =TEXT(B33,"mmmm") -> October | P33: =YEAR(B33) -> 2024 | Q33: =_xlfn.CONCAT(SALES[[#This Row],[Sales_ID]]," [",SALES[[#This Row],[Quantity]],"]") -> SALE-31 [2]
A34: SALE-32 | B34: 45597 | C34: CUST-1398 | D34: PROD-75 | E34: STORE-8 | F34: 4 | G34: 313.83 | H34: 0.08 | I34: CREDIT CARD | J34: 1154.8944 | K34: =SALES[[#This Row],[Quantity]]*SALES[[#This Row],[Unit_Price]]*SALES[[#This Row],[Discount]] -> 100.4256 | L34: =IF(SALES[Total_Amount]>=1500,"High","Low") -> Low | M34: =_xlfn.IFS(J34>2000,"Premium",J34>1000,"High",J34<=1000,"Normal") -> High | N34: =IF(AND(H34>15%,J34>1000),"High Price","Low Price") -> Low Price | O34: =TEXT(B34,"mmmm") -> November | P34: =YEAR(B34) -> 2024 | Q34: =_xlfn.CONCAT(SALES[[#This Row],[Sales_ID]]," [",SALES[[#This Row],[Quantity]],"]") -> SALE-32 [4]
A35: SALE-33 | B35: 45620 | C35: CUST-1453 | D35: PROD-12 | E35: STORE-6 | F35: 2 | G35: 717.31 | H35: 0.15 | I35: CREDIT CARD | J35: 1219.427 | K35: =SALES[[#This Row],[Quantity]]*SALES[[#This Row],[Unit_Price]]*SALES[[#This Row],[Discount]] -> 215.193 | L35: =IF(SALES[Total_Amount]>=1500,"High","Low") -> Low | M35: =_xlfn.IFS(J35>2000,"Premium",J35>1000,"High",J35<=1000,"Normal") -> High | N35: =IF(AND(H35>15%,J35>1000),"High Price","Low Price") -> Low Price | O35: =TEXT(B35,"mmmm") -> November | P35: =YEAR(B35) -> 2024 | Q35: =_xlfn.CONCAT(SALES[[#This Row],[Sales_ID]]," [",SALES[[#This Row],[Quantity]],"]") -> SALE-33 [2]
A36: SALE-34 | B36: 45215 | C36: CUST-1344 | D36: PROD-79 | E36: STORE-1 | F36: 2 | G36: 873.22 | H36: 0.18 | I36: CREDIT CARD | J36: 2148.1212 | K36: =SALES[[#This Row],[Quantity]]*SALES[[#This Row],[Unit_Price]]*SALES[[#This Row],[Discount]] -> 314.3592 | L36: =IF(SALES[Total_Amount]>=1500,"High","Low") -> High | M36: =_xlfn.IFS(J36>2000,"Premium",J36>1000,"High",J36<=1000,"Normal") -> Premium | N36: =IF(AND(H36>15%,J36>1000),"High Price","Low Price") -> High Price | O36: =TEXT(B36,"mmmm") -> October | P36: =YEAR(B36) -> 2023 | Q36: =_xlfn.CONCAT(SALES[[#This Row],[Sales_ID]]," [",SALES[[#This Row],[Quantity]],"]") -> SALE-34 [2]
A37: SALE-35 | B37: 45878 | C37: CUST-1218 | D37: PROD-16 | E37: STORE-3 | F37: 4 | G37: 109.36 | H37: 0.19 | I37: COD | J37: 354.3264 | K37: =SALES[[#This Row],[Quantity]]*SALES[[#This Row],[Unit_Price]]*SALES[[#This Row],[Discount]] -> 83.1136 | L37: =IF(SALES[Total_Amount]>=1500,"High","Low") -> Low | M37: =_xlfn.IFS(J37>2000,"Premium",J37>1000,"High",J37<=1000,"Normal") -> Normal | N37: =IF(AND(H37>15%,J37>1000),"High Price","Low Price") -> Low Price | O37: =TEXT(B37,"mmmm") -> August | P37: =YEAR(B37) -> 2025 | Q37: =_xlfn.CONCAT(SALES[[#This Row],[Sales_ID]]," [",SALES[[#This Row],[Quantity]],"]") -> SALE-35 [4]
... A53: SALE-51 | B53: 45689 | C53: CUST-1142 | D53: PROD-69 | E53: STORE-7 | F53: 3 | G53: 76.57 | H53: 0.26 | I53: CREDIT CARD | J53: 169.9854 | K53: =SALES[[#This Row],[Quantity]]*SALES[[#This Row],[Unit_Price]]*SALES[[#This Row],[Discount]] -> 59.7246 | L53: =IF(SALES[Total_Amount]>=1500,"High","Low") -> Low | M53: =_xlfn.IFS(J53>2000,"Premium",J53>1000,"High",J53<=1000,"Normal") -> Normal | N53: =IF(AND(H53>15%,J53>1000),"High Price","Low Price") -> Low Price | O53: =TEXT(B53,"mmmm") -> February | P53: =YEAR(B53) -> 2025 | Q53: =_xlfn.CONCAT(SALES[[#This Row],[Sales_ID]]," [",SALES[[#This Row],[Quantity]],"]") -> SALE-51 [3]
A54: SALE-52 | B54: 45894 | C54: CUST-1148 | D54: PROD-89 | E54: STORE-6 | F54: 3 | G54: =SALES[[#This Row],[Total_Amount]]/(SALES[[#This Row],[Quantity]]*(1-SALES[[#This Row],[Discount]])) -> 190.61306 | H54: 0.15 | I54: CREDIT CARD | J54: 486.0633 | K54: =SALES[[#This Row],[Quantity]]*SALES[[#This Row],[Unit_Price]]*SALES[[#This Row],[Discount]] -> 85.775876 | L54: =IF(SALES[Total_Amount]>=1500,"High","Low") -> Low | M54: =_xlfn.IFS(J54>2000,"Premium",J54>1000,"High",J54<=1000,"Normal") -> Normal | N54: =IF(AND(H54>15%,J54>1000),"High Price","Low Price") -> Low Price | O54: =TEXT(B54,"mmmm") -> August | P54: =YEAR(B54) -> 2025 | Q54: =_xlfn.CONCAT(SALES[[#This Row],[Sales_ID]]," [",SALES[[#This Row],[Quantity]],"]") -> SALE-52 [3]
A55: SALE-53 | B55: 45677 | C55: CUST-1324 | D55: PROD-20 | E55: STORE-8 | F55: 1 | G55: 900.35 | H55: 0.13 | I55: COD | J55: 783.3045 | K55: =SALES[[#This Row],[Quantity]]*SALES[[#This Row],[Unit_Price]]*SALES[[#This Row],[Discount]] -> 117.0455 | L55: =IF(SALES[Total_Amount]>=1500,"High","Low") -> Low | M55: =_xlfn.IFS(J55>2000,"Premium",J55>1000,"High",J55<=1000,"Normal") -> Normal | N55: =IF(AND(H55>15%,J55>1000),"High Price","Low Price") -> Low Price | O55: =TEXT(B55,"mmmm") -> January | P55: =YEAR(B55) -> 2025 | Q55: =_xlfn.CONCAT(SALES[[#This Row],[Sales_ID]]," [",SALES[[#This Row],[Quantity]],"]") -> SALE-53 [1]
...

Sheet Statistics
A1: Descriptive statistics
B6: Descriptive statistics for Total amount in SALES Table | F6: Descriptive statistics for Cost in PRODUCT Table
B8: Mean | C8: 1087.1973 | F8: Mean | G8: 273.48
B9: Standard Error | C9: 18.327237 | F9: Standard Error | G9: 12.995046
B10: Median | C10: 868.7182 | F10: Median | G10: 273
B11: Mode | C11: #N/A | F11: Mode | G11: 273
B12: Standard Deviation | C12: 819.61896 | F12: Standard Deviation | G12: 129.95046
B13: Sample Variance | C13: 671775.25 | F13: Sample Variance | G13: 16887.121
B14: Kurtosis | C14: 0.045826153 | F14: Kurtosis | G14: -1.1529465
B15: Skewness | C15: 0.87904704 | F15: Skewness | G15: -0.0073416277
B16: Range | C16: 3889.7838 | F16: Range | G16: 439
B17: Minimum | C17: 18.459 | F17: Minimum | G17: 57
B18: Maximum | C18: 3908.2428 | F18: Maximum | G18: 496
B19: Sum | C19: 2174394.7 | F19: Sum | G19: 27348
B20: Count | C20: 2000 | F20: Count | G20: 100
B21: Largest(1) | C21: 3908.2428 | F21: Largest(1) | G21: 496
B22: Smallest(1) | C22: 18.459 | F22: Smallest(1) | G22: 57
B23: Confidence Level(95.0%) | C23: 35.942487 | F23: Confidence Level(95.0%) | G23: 25.78499

Sheet Lookup
A1: VLOOKUP
C9: Created a VLOOKUP to return the Loyalty_Level and Customer Name | J9: Created a VLOOKUP to return the Product_Name,Category and Cost.
C11: Customer_ID | D11: Customer_Name | E11: Loyalty_Level | J11: Product_ID | K11: Product_Name | L11: Category | M11: Cost
C12: CUST-1000 | D12: =VLOOKUP(C12,Customer_Dim!A:H,2,FALSE) -> Sheena Bonilla | E12: =VLOOKUP(D12,Customer_Dim!B:I,7,FALSE) -> Platinum | J12: PROD-15 | K12: =VLOOKUP(J12,PRODUCT[],2,FALSE) -> 4K Home Projector | L12: =VLOOKUP(J12,Product_Dim!A:G,3,FALSE) -> Electronics | M12: =VLOOKUP(K12,Product_Dim!B:G,6,FALSE) -> 301
C13: CUST-1010 | D13: =VLOOKUP(C13,Customer_Dim!A:H,2,FALSE) -> Dominic Page | E13: =VLOOKUP(D13,Customer_Dim!B:I,7,FALSE) -> Bronze | J13: PROD-26 | K13: =VLOOKUP(J13,PRODUCT[],2,FALSE) -> Wireless Bluetooth Speaker | L13: =VLOOKUP(J13,Product_Dim!A:G,3,FALSE) -> Electronics | M13: =VLOOKUP(K13,Product_Dim!B:G,6,FALSE) -> 213
C14: CUST-1020 | D14: =VLOOKUP(C14,Customer_Dim!A:H,2,FALSE) -> Bridget Allen | E14: =VLOOKUP(D14,Customer_Dim!B:I,7,FALSE) -> Silver | J14: PROD-17 | K14: =VLOOKUP(J14,PRODUCT[],2,FALSE) -> Soccer Training Cone Set | L14: =VLOOKUP(J14,Product_Dim!A:G,3,FALSE) -> Sports | M14: =VLOOKUP(K14,Product_Dim!B:G,6,FALSE) -> 367
C15: CUST-1030 | D15: =VLOOKUP(C15,Customer_Dim!A:H,2,FALSE) -> Jessica Acevedo | E15: =VLOOKUP(D15,Customer_Dim!B:I,7,FALSE) -> Bronze | J15: PROD-24 | K15: =VLOOKUP(J15,PRODUCT[],2,FALSE) -> Foldable Camping Chair | L15: =VLOOKUP(J15,Product_Dim!A:G,3,FALSE) -> Sports | M15: =VLOOKUP(K15,Product_Dim!B:G,6,FALSE) -> 340
C16: CUST-1040 | D16: =VLOOKUP(C16,Customer_Dim!A:H,2,FALSE) -> Eric Vega | E16: =VLOOKUP(D16,Customer_Dim!B:I,7,FALSE) -> Gold | J16: PROD-19 | K16: =VLOOKUP(J16,PRODUCT[],2,FALSE) -> Knee Support Brace | L16: =VLOOKUP(J16,Product_Dim!A:G,3,FALSE) -> Sports | M16: =VLOOKUP(K16,Product_Dim!B:G,6,FALSE) -> 65
C17: CUST-1050 | D17: =VLOOKUP(C17,Customer_Dim!A:H,2,FALSE) -> Matthew Hunter Jr. | E17: =VLOOKUP(D17,Customer_Dim!B:I,7,FALSE) -> Gold | J17: PROD-20 | K17: =VLOOKUP(J17,PRODUCT[],2,FALSE) -> Outdoor Sports Water Bottle | L17: =VLOOKUP(J17,Product_Dim!A:G,3,FALSE) -> Sports | M17: =VLOOKUP(K17,Product_Dim!B:G,6,FALSE) -> 273
C18: CUST-1060 | D18: =VLOOKUP(C18,Customer_Dim!A:H,2,FALSE) -> Dr. David Smith | E18: =VLOOKUP(D18,Customer_Dim!B:I,7,FALSE) -> Silver | J18: PROD-25 | K18: =VLOOKUP(J18,PRODUCT[],2,FALSE) -> Women's Scarf Set | L18: =VLOOKUP(J18,Product_Dim!A:G,3,FALSE) -> Clothing | M18: =VLOOKUP(K18,Product_Dim!B:G,6,FALSE) -> 268
C19: CUST-1070 | D19: =VLOOKUP(C19,Customer_Dim!A:H,2,FALSE) -> Eric Singh | E19: =VLOOKUP(D19,Customer_Dim!B:I,7,FALSE) -> Gold | J19: PROD-22 | K19: =VLOOKUP(J19,PRODUCT[],2,FALSE) -> Carbon Fiber Tennis Racket | L19: =VLOOKUP(J19,Product_Dim!A:G,3,FALSE) -> Sports | M19: =VLOOKUP(K19,Product_Dim!B:G,6,FALSE) -> 432
C20: CUST-1080 | D20: =VLOOKUP(C20,Customer_Dim!A:H,2,FALSE) -> Jennifer Garcia | E20: =VLOOKUP(D20,Customer_Dim!B:I,7,FALSE) -> Bronze | J20: PROD-23 | K20: =VLOOKUP(J20,PRODUCT[],2,FALSE) -> Men's Formal Shirt | L20: =VLOOKUP(J20,Product_Dim!A:G,3,FALSE) -> Clothing | M20: =VLOOKUP(K20,Product_Dim!B:G,6,FALSE) -> 360
C21: CUST-1090 | D21: =VLOOKUP(C21,Customer_Dim!A:H,2,FALSE) -> Oscar Moon | E21: =VLOOKUP(D21,Customer_Dim!B:I,7,FALSE) -> Platinum

Sheet Pivot
A1: Pivot Table
B5: Category Wise Total Sales | F5: Distribution of orders based on quantity | L5: Yearly Total Sales(Payment Type) | R5: Monthly Total Sales
B7: CATEGORY | C7: Sum of Total_Amount | F7: QUANTITY | G7: Count of Quantity | L7: Average of Total_Amount | R7: MONTH | S7: Average of Total_Amount
B8: Beauty | C8: 321561.33 | F8: 1 | G8: 503 | L8: YEAR | M8: COD | N8: CREDIT CARD | O8: PAYPAL | P8: Grand Total | R8: April | S8: 1197.9133
B9: Clothing | C9: 379216.04 | F9: 2 | G9: 517 | L9: 2023 | M9: 964.14501 | N9: 1173.1532 | O9: 958.0739 | P9: 1031.395 | R9: August | S9: 1123.7411
B10: Electronics | C10: 504311.35 | F10: 3 | G10: 499 | L10: 2024 | M10: 1095.736 | N10: 1054.2214 | O10: 1127.8511 | P10: 1095.0068 | R10: December | S10: 1096.7364
B11: Home | C11: 427295.8 | F11: 4 | G11: 481 | L11: 2025 | M11: 1051.9529 | N11: 1152.9059 | O11: 1070.6055 | P11: 1092.6916 | R11: February | S11: 975.30779
B12: Sports | C12: 542010.17 | F12: Grand Total | G12: 2000 | L12: Grand Total | M12: 1064.3324 | N12: 1108.8073 | O12: 1088.8555 | P12: 1087.1973 | R12: January | S12: 1063.7143
B13: Grand Total | C13: 2174394.7 | R13: July | S13: 1058.2164
R14: June | S14: 1049.2904
R15: March | S15: 1151.3908
R16: May | S16: 927.2909
B17: Store Comparison | R17: November | S17: 1128.8323
R18: October | S18: 1114.7797
B19: Sum Of Month | R19: September | S19: 1142.8496
B20: STORE NAME | C20: January | D20: February | E20: March | F20: April | G20: May | H20: June | I20: July | J20: August | K20: September | L20: October | M20: November | N20: December | O20: Grand Total | P20: SPARKLINE | R20: Grand Total | S20: 1087.1973
B21: Aguirre-Keller | C21: 13506.438 | D21: 4596.534 | E21: 7613.0898 | F21: 10947.305 | G21: 8051.8123 | H21: 3819.8173 | I21: 8240.461 | J21: 4921.7558 | K21: 8329.0394 | L21: 8653.4096 | M21: 7844.618 | N21: 6523.8602 | O21: 93048.141
B22: Alexander Group | C22: 12466.574 | D22: 8869.7779 | E22: 6385.047 | F22: 5155.2824 | G22: 5422.8924 | H22: 9953.0073 | I22: 15597.94 | J22: 14179.442 | K22: 10462.848 | L22: 12273.833 | M22: 7279.8783 | N22: 10767.594 | O22: 118814.12
B23: Bean, Jones And Park | C23: 5118.3181 | D23: 8493.8756 | E23: 17640.435 | F23: 18641.138 | G23: 17062.762 | H23: 9611.8812 | I23: 23159.908 | J23: 10623.933 | K23: 10916.525 | L23: 11892.214 | M23: 11711.057 | N23: 14099.417 | O23: 158971.46
B24: Benson-Elliott | C24: 9409.1192 | D24: 10798.99 | E24: 10977.256 | F24: 1587.3115 | G24: 4204.6758 | H24: 7562.4438 | I24: 8623.4275 | J24: 9182.7821 | K24: 18011.667 | L24: 9635.4122 | M24: 12749.731 | N24: 11790.98 | O24: 114533.8
B25: Black-Horn | C25: 9815.2253 | D25: 2769.6424 | E25: 7192.6516 | F25: 8701.9976 | G25: 3820.9498 | H25: 4080.7001 | I25: 8880.0349 | J25: 8882.5801 | K25: 13846.224 | L25: 17195.315 | M25: 10168.917 | N25: 3606.5697 | O25: 98960.808
B26: Frederick-Wright | C26: 6554.5663 | D26: 4790.8882 | E26: 8357.0949 | F26: 10919.551 | G26: 9466.9366 | H26: 16595.156 | I26: 4967.5702 | J26: 16754.64 | K26: 18865.788 | L26: 9036.8504 | M26: 2146.8943 | N26: 3249.007 | O26: 111704.94
B27: Gardner, Humphrey And Contreras | C27: 8915.2955 | D27: 13299.605 | E27: 19220.915 | F27: 9893.045 | G27: 10494.129 | H27: 9842.5487 | I27: 7297.6138 | J27: 5700.2547 | K27: 9956.8121 | L27: 8029.7279 | M27: 5144.5797 | N27: 6606.9444 | O27: 114401.47
B28: Gray Ltd | C28: 9622.8533 | D28: 3784.7462 | E28: 8950.2397 | F28: 2847.5059 | G28: 5601.1133 | H28: 4227.5326 | I28: 9775.5133 | J28: 7714.789 | K28: 4361.9932 | L28: 2086.445 | M28: 15085.631 | N28: 7285.2264 | O28: 81343.589
B29: Guerrero-Schmitt | C29: 10174.881 | D29: 9912.2631 | E29: 5656.7449 | F29: 9563.7194 | G29: 8823.9095 | H29: 5343.1444 | I29: 11497.915 | J29: 9724.3917 | K29: 5670.209 | L29: 10257.357 | M29: 9766.934 | N29: 7921.5868 | O29: 104313.05
B30: Hill, Wagner And Ballard | C30: 2940.4488 | D30: 9604.0314 | E30: 4973.8146 | F30: 17851.011 | G30: 11866.669 | H30: 12228.923 | I30: 8603.0291 | J30: 8499.4124 | K30: 10679.624 | L30: 10288.397 | M30: 7325.8474 | N30: 4930.5068 | O30: 109791.72
B31: Holloway Ltd | C31: 12105.371 | D31: 5361.9398 | E31: 10232.366 | F31: 11142.908 | G31: 6583.7804 | H31: 21845.566 | I31: 10995.029 | J31: 9903.8596 | K31: 12220.827 | L31: 5169.3003 | M31: 6734.5268 | N31: 9881.0727 | O31: 122176.55
B32: Johnson-Wright | C32: 9531.6295 | D32: 12725.45 | E32: 14503.217 | F32: 11538.719 | G32: 10677.545 | H32: 3830.9304 | I32: 3320.7956 | J32: 6884.9095 | K32: 15006.15 | L32: 15333.019 | M32: 13321.293 | N32: 8338.1706 | O32: 125011.83
... B41: Grand Total | C41: 174449.14 | D41: 155073.94 | E41: 210704.52 | F41: 192864.04 | G41: 146511.96 | H41: 162640.02 | I41: 194711.82 | J41: 192159.73 | K41: 188570.18 | L41: 186168.21 | M41: 187386.17 | N41: 183154.98 | O41: 2174394.7

Sheet Charts
A1: Charts
A6: Pie Chart | I6: Column Chart
A8: Category Wise Total Sales | I8: Yearly Total Sales(Payment Type)
A28: Line Chart | K28: Scatter Chart
A30: Monthly Sales Trend | K30: Distribution of orders based on quantity
M32: 1 | N32: 503
M33: 2 | N33: 517
M34: 3 | N34: 499
M35: 4 | N35: 481

Sheet Dashboard
A1: E-commerce store dataset
